<?xml version="1.0"?> <robot name="Sk8t3rBot"><link name="rink">     <origin xyz="0 0 0" />    <visual>        <geometry>            <box size="100 100 0.0001" />        </geometry>        <material>            <color rgba="0.86 0.945 0.98 1" />        </material>    </visual></link><joint name="rink_world" type="fixed">    <parent link="world" />    <child link="rink" /></joint><link name="body"><inertial>     <origin xyz="0 0 0.25" />     <mass value="50" />     <inertia ixx="1.1354166666666665"  ixy="0"  ixz="0" iyy="2.083333333333333" iyz="0" izz="1.1354166666666665" /> </inertial><visual> <origin xyz="0 0 0.25" /> <origin xyz="0 0 0.25" /> <geometry> <box size="0.5 0.15 0.5" /> </geometry> <material> <color rgba="0 1 0 1" /></material> </visual></link><link name="inner_hip" /> <joint name="inner_hip_joint" type="continuous">     <origin xyz="0 0 0" />     <parent link="inner_hip" />     <child link="body" />     <axis xyz="0 0 1" /> </joint> <transmission>     <joint name="inner_hip_joint" />     <actuator name="inner_hip_act" />     <type>transmission_interface/SimpleTransmission</type> </transmission><link name="hip" /> <joint name="hip_joint" type="continuous">     <origin xyz="0 0 0" />     <parent link="hip" />     <child link="inner_hip" />     <axis xyz="0 1 0" /> </joint> <transmission>     <joint name="hip_joint" />     <actuator name="hip_act" />     <type>transmission_interface/SimpleTransmission</type> </transmission><link name="upper_leg">     <inertial>         <origin xyz="0 0 0.1" />         <mass value="10" />         <inertia ixx="0.05208333333333333"  ixy="0"  ixz="0" iyy="0.06666666666666668" iyz="0" izz="0.05208333333333333" />     </inertial>     <visual>         <origin xyz="0 0 0.1" />         <geometry> <box size="0.2 0.15 0.2" /> </geometry>         <material> <color rgba="1 0 0 1" /></material>     </visual> </link> <joint name="phi" type="continuous">     <origin xyz="0 0 0.2" />     <parent link="upper_leg" />     <child link="hip" />     <axis xyz="1 0 0" /> </joint> <transmission>     <joint name="phi" />     <actuator name="phi_act" />     <type>transmission_interface/SimpleTransmission</type> </transmission><link name="lower_leg">     <inertial>         <origin xyz="0 0 0.1" />         <mass value="10" />         <inertia ixx="0.05208333333333333"  ixy="0"  ixz="0" iyy="0.06666666666666668" iyz="0" izz="0.05208333333333333" />     </inertial>     <visual>         <origin xyz="0 0 0.1" />         <geometry> <box size="0.2 0.15 0.2" /> </geometry>         <material> <color rgba="0 0 1 1" /></material>     </visual> </link> <joint name="knee" type="continuous">     <origin xyz="0 0 0.2" />     <parent link="lower_leg" />     <child link="upper_leg" />     <axis xyz="1 0 0" /> </joint> <transmission>     <joint name="knee" />     <actuator name="knee_act" />     <type>transmission_interface/SimpleTransmission</type> </transmission><link name="blade">     <inertial>         <mass value="2" />,         <inertia ixx="0.027083333333333338"  ixy="0"  ixz="0" iyy="0.00043333333333333337" iyz="0" izz="0.026683333333333337" />,     </inertial>     <visual>         <origin xyz="0 0 0.025" />         <geometry> <box size="0.01 0.4 0.05" /> </geometry>     </visual> </link> <joint name="ankle" type="continuous">     <origin xyz="0 0 0.05" />     <parent link="blade" />     <child link="lower_leg" /> </joint> <transmission>     <joint name="ankle" />     <actuator name="ankle_act" />     <type>transmission_interface/SimpleTransmission</type> </transmission></robot></xml>